Workbook

Sheet Emp Info
A1: FullName | B1: PrimaryEmail🔂 | C1: sapce | D1: FirstName 🔂 | E1: LastName 🔂 | F1: PrimaryEmail | G1: Password 🔂
A2: Aman Hans | B2: =IFERROR(__xludf.DUMMYFUNCTION("IF(A2<>"""", IF(COUNTA(SPLIT(TRIM(A2), "" ""))=1, LOWER(TRIM(A2)) & ""@zupee.in"", LOWER(INDEX(SPLIT(TRIM(A2), "" ""), 1)) & ""."" & LOWER(INDEX(SPLIT(TRIM(A2), "" ""), COUNTA(SPLIT(TRIM(A2), "" "")))) & ""@zupee.in"" ), """")"),"aman.hans@zupee.in") -> aman.hans@zupee.in | D2: =IFERROR(LEFT('Emp Info'!A2,SEARCH(" ",'Emp Info'!A2)-1),'Emp Info'!A2) -> Aman | E2: =IF(ISBLANK('Emp Info'!A2), "", IFERROR(RIGHT('Emp Info'!A2,LEN('Emp Info'!A2)-SEARCH(" ",'Emp Info'!A2,1)),".")) -> Hans | F2: =IFERROR(__xludf.DUMMYFUNCTION("IF('Emp Info'!A2<>"""", IF(COUNTA(SPLIT(TRIM('Emp Info'!A2), "" ""))=1, LOWER(TRIM('Emp Info'!A2)) & ""@zupee.in"", LOWER(INDEX(SPLIT(TRIM('Emp Info'!A2), "" ""), 1)) & ""."" & LOWER(INDEX(SPLIT(TRIM('Emp Info'!A2), "" ""), COUNTA(SPLIT("&"TRIM('Emp Info'!A2), "" "")))) & ""@zupee.in"" ), """")"),"aman.hans@zupee.in") -> aman.hans@zupee.in
A3: Harshit Kumar Singh | B3: =IFERROR(__xludf.DUMMYFUNCTION("IF(A3<>"""", IF(COUNTA(SPLIT(TRIM(A3), "" ""))=1, LOWER(TRIM(A3)) & ""@zupee.in"", LOWER(INDEX(SPLIT(TRIM(A3), "" ""), 1)) & ""."" & LOWER(INDEX(SPLIT(TRIM(A3), "" ""), COUNTA(SPLIT(TRIM(A3), "" "")))) & ""@zupee.in"" ), """")"),"harshit.singh@zupee.in") -> harshit.singh@zupee.in | D3: =IFERROR(LEFT('Emp Info'!A3,SEARCH(" ",'Emp Info'!A3)-1),'Emp Info'!A3) -> Harshit | E3: =IF(ISBLANK('Emp Info'!A3), "", IFERROR(RIGHT('Emp Info'!A3,LEN('Emp Info'!A3)-SEARCH(" ",'Emp Info'!A3,1)),".")) -> Kumar Singh | F3: =IFERROR(__xludf.DUMMYFUNCTION("IF('Emp Info'!A3<>"""", IF(COUNTA(SPLIT(TRIM('Emp Info'!A3), "" ""))=1, LOWER(TRIM('Emp Info'!A3)) & ""@zupee.in"", LOWER(INDEX(SPLIT(TRIM('Emp Info'!A3), "" ""), 1)) & ""."" & LOWER(INDEX(SPLIT(TRIM('Emp Info'!A3), "" ""), COUNTA(SPLIT("&"TRIM('Emp Info'!A3), "" "")))) & ""@zupee.in"" ), """")"),"harshit.singh@zupee.in") -> harshit.singh@zupee.in
B4: =IFERROR(__xludf.DUMMYFUNCTION("IF(A4<>"""", IF(COUNTA(SPLIT(TRIM(A4), "" ""))=1, LOWER(TRIM(A4)) & ""@zupee.in"", LOWER(INDEX(SPLIT(TRIM(A4), "" ""), 1)) & ""."" & LOWER(INDEX(SPLIT(TRIM(A4), "" ""), COUNTA(SPLIT(TRIM(A4), "" "")))) & ""@zupee.in"" ), """")"),"") | E4: =IF(ISBLANK('Emp Info'!A4), "", IFERROR(RIGHT('Emp Info'!A4,LEN('Emp Info'!A4)-SEARCH(" ",'Emp Info'!A4,1)),"."))
B5: =IFERROR(__xludf.DUMMYFUNCTION("IF(A5<>"""", IF(COUNTA(SPLIT(TRIM(A5), "" ""))=1, LOWER(TRIM(A5)) & ""@zupee.in"", LOWER(INDEX(SPLIT(TRIM(A5), "" ""), 1)) & ""."" & LOWER(INDEX(SPLIT(TRIM(A5), "" ""), COUNTA(SPLIT(TRIM(A5), "" "")))) & ""@zupee.in"" ), """")"),"")
B6: =IFERROR(__xludf.DUMMYFUNCTION("IF(A6<>"""", IF(COUNTA(SPLIT(TRIM(A6), "" ""))=1, LOWER(TRIM(A6)) & ""@zupee.in"", LOWER(INDEX(SPLIT(TRIM(A6), "" ""), 1)) & ""."" & LOWER(INDEX(SPLIT(TRIM(A6), "" ""), COUNTA(SPLIT(TRIM(A6), "" "")))) & ""@zupee.in"" ), """")"),"")
B7: =IFERROR(__xludf.DUMMYFUNCTION("IF(A7<>"""", IF(COUNTA(SPLIT(TRIM(A7), "" ""))=1, LOWER(TRIM(A7)) & ""@zupee.in"", LOWER(INDEX(SPLIT(TRIM(A7), "" ""), 1)) & ""."" & LOWER(INDEX(SPLIT(TRIM(A7), "" ""), COUNTA(SPLIT(TRIM(A7), "" "")))) & ""@zupee.in"" ), """")"),"")
B8: =IFERROR(__xludf.DUMMYFUNCTION("IF(A8<>"""", IF(COUNTA(SPLIT(TRIM(A8), "" ""))=1, LOWER(TRIM(A8)) & ""@zupee.in"", LOWER(INDEX(SPLIT(TRIM(A8), "" ""), 1)) & ""."" & LOWER(INDEX(SPLIT(TRIM(A8), "" ""), COUNTA(SPLIT(TRIM(A8), "" "")))) & ""@zupee.in"" ), """")"),"")
B9: =IFERROR(__xludf.DUMMYFUNCTION("IF(A9<>"""", IF(COUNTA(SPLIT(TRIM(A9), "" ""))=1, LOWER(TRIM(A9)) & ""@zupee.in"", LOWER(INDEX(SPLIT(TRIM(A9), "" ""), 1)) & ""."" & LOWER(INDEX(SPLIT(TRIM(A9), "" ""), COUNTA(SPLIT(TRIM(A9), "" "")))) & ""@zupee.in"" ), """")"),"")
B10: =IFERROR(__xludf.DUMMYFUNCTION("IF(A10<>"""", IF(COUNTA(SPLIT(TRIM(A10), "" ""))=1, LOWER(TRIM(A10)) & ""@zupee.in"", LOWER(INDEX(SPLIT(TRIM(A10), "" ""), 1)) & ""."" & LOWER(INDEX(SPLIT(TRIM(A10), "" ""), COUNTA(SPLIT(TRIM(A10), "" "")))) & ""@zupee.in"" ), """&""")"),"")
B11: =IFERROR(__xludf.DUMMYFUNCTION("IF(A11<>"""", IF(COUNTA(SPLIT(TRIM(A11), "" ""))=1, LOWER(TRIM(A11)) & ""@zupee.in"", LOWER(INDEX(SPLIT(TRIM(A11), "" ""), 1)) & ""."" & LOWER(INDEX(SPLIT(TRIM(A11), "" ""), COUNTA(SPLIT(TRIM(A11), "" "")))) & ""@zupee.in"" ), """&""")"),"")
B12: =IFERROR(__xludf.DUMMYFUNCTION("IF(A12<>"""", IF(COUNTA(SPLIT(TRIM(A12), "" ""))=1, LOWER(TRIM(A12)) & ""@zupee.in"", LOWER(INDEX(SPLIT(TRIM(A12), "" ""), 1)) & ""."" & LOWER(INDEX(SPLIT(TRIM(A12), "" ""), COUNTA(SPLIT(TRIM(A12), "" "")))) & ""@zupee.in"" ), """&""")"),"")
B13: =IFERROR(__xludf.DUMMYFUNCTION("IF(A13<>"""", IF(COUNTA(SPLIT(TRIM(A13), "" ""))=1, LOWER(TRIM(A13)) & ""@zupee.in"", LOWER(INDEX(SPLIT(TRIM(A13), "" ""), 1)) & ""."" & LOWER(INDEX(SPLIT(TRIM(A13), "" ""), COUNTA(SPLIT(TRIM(A13), "" "")))) & ""@zupee.in"" ), """&""")"),"")
B14: =IFERROR(__xludf.DUMMYFUNCTION("IF(A14<>"""", IF(COUNTA(SPLIT(TRIM(A14), "" ""))=1, LOWER(TRIM(A14)) & ""@zupee.in"", LOWER(INDEX(SPLIT(TRIM(A14), "" ""), 1)) & ""."" & LOWER(INDEX(SPLIT(TRIM(A14), "" ""), COUNTA(SPLIT(TRIM(A14), "" "")))) & ""@zupee.in"" ), """&""")"),"")
B15: =IFERROR(__xludf.DUMMYFUNCTION("IF(A15<>"""", IF(COUNTA(SPLIT(TRIM(A15), "" ""))=1, LOWER(TRIM(A15)) & ""@zupee.in"", LOWER(INDEX(SPLIT(TRIM(A15), "" ""), 1)) & ""."" & LOWER(INDEX(SPLIT(TRIM(A15), "" ""), COUNTA(SPLIT(TRIM(A15), "" "")))) & ""@zupee.in"" ), """&""")"),"")
B16: =IFERROR(__xludf.DUMMYFUNCTION("IF(A16<>"""", IF(COUNTA(SPLIT(TRIM(A16), "" ""))=1, LOWER(TRIM(A16)) & ""@zupee.in"", LOWER(INDEX(SPLIT(TRIM(A16), "" ""), 1)) & ""."" & LOWER(INDEX(SPLIT(TRIM(A16), "" ""), COUNTA(SPLIT(TRIM(A16), "" "")))) & ""@zupee.in"" ), """&""")"),"")
B17: =IFERROR(__xludf.DUMMYFUNCTION("IF(A17<>"""", IF(COUNTA(SPLIT(TRIM(A17), "" ""))=1, LOWER(TRIM(A17)) & ""@zupee.in"", LOWER(INDEX(SPLIT(TRIM(A17), "" ""), 1)) & ""."" & LOWER(INDEX(SPLIT(TRIM(A17), "" ""), COUNTA(SPLIT(TRIM(A17), "" "")))) & ""@zupee.in"" ), """&""")"),"")
B18: =IFERROR(__xludf.DUMMYFUNCTION("IF(A18<>"""", IF(COUNTA(SPLIT(TRIM(A18), "" ""))=1, LOWER(TRIM(A18)) & ""@zupee.in"", LOWER(INDEX(SPLIT(TRIM(A18), "" ""), 1)) & ""."" & LOWER(INDEX(SPLIT(TRIM(A18), "" ""), COUNTA(SPLIT(TRIM(A18), "" "")))) & ""@zupee.in"" ), """&""")"),"")
B19: =IFERROR(__xludf.DUMMYFUNCTION("IF(A19<>"""", IF(COUNTA(SPLIT(TRIM(A19), "" ""))=1, LOWER(TRIM(A19)) & ""@zupee.in"", LOWER(INDEX(SPLIT(TRIM(A19), "" ""), 1)) & ""."" & LOWER(INDEX(SPLIT(TRIM(A19), "" ""), COUNTA(SPLIT(TRIM(A19), "" "")))) & ""@zupee.in"" ), """&""")"),"")
B20: =IFERROR(__xludf.DUMMYFUNCTION("IF(A20<>"""", IF(COUNTA(SPLIT(TRIM(A20), "" ""))=1, LOWER(TRIM(A20)) & ""@zupee.in"", LOWER(INDEX(SPLIT(TRIM(A20), "" ""), 1)) & ""."" & LOWER(INDEX(SPLIT(TRIM(A20), "" ""), COUNTA(SPLIT(TRIM(A20), "" "")))) & ""@zupee.in"" ), """&""")"),"")
B21: =IFERROR(__xludf.DUMMYFUNCTION("IF(A21<>"""", IF(COUNTA(SPLIT(TRIM(A21), "" ""))=1, LOWER(TRIM(A21)) & ""@zupee.in"", LOWER(INDEX(SPLIT(TRIM(A21), "" ""), 1)) & ""."" & LOWER(INDEX(SPLIT(TRIM(A21), "" ""), COUNTA(SPLIT(TRIM(A21), "" "")))) & ""@zupee.in"" ), """&""")"),"")
B22: =IFERROR(__xludf.DUMMYFUNCTION("IF(A22<>"""", IF(COUNTA(SPLIT(TRIM(A22), "" ""))=1, LOWER(TRIM(A22)) & ""@zupee.in"", LOWER(INDEX(SPLIT(TRIM(A22), "" ""), 1)) & ""."" & LOWER(INDEX(SPLIT(TRIM(A22), "" ""), COUNTA(SPLIT(TRIM(A22), "" "")))) & ""@zupee.in"" ), """&""")"),"")
B23: =IFERROR(__xludf.DUMMYFUNCTION("IF(A23<>"""", IF(COUNTA(SPLIT(TRIM(A23), "" ""))=1, LOWER(TRIM(A23)) & ""@zupee.in"", LOWER(INDEX(SPLIT(TRIM(A23), "" ""), 1)) & ""."" & LOWER(INDEX(SPLIT(TRIM(A23), "" ""), COUNTA(SPLIT(TRIM(A23), "" "")))) & ""@zupee.in"" ), """&""")"),"")
B24: =IFERROR(__xludf.DUMMYFUNCTION("IF(A24<>"""", IF(COUNTA(SPLIT(TRIM(A24), "" ""))=1, LOWER(TRIM(A24)) & ""@zupee.in"", LOWER(INDEX(SPLIT(TRIM(A24), "" ""), 1)) & ""."" & LOWER(INDEX(SPLIT(TRIM(A24), "" ""), COUNTA(SPLIT(TRIM(A24), "" "")))) & ""@zupee.in"" ), """&""")"),"")
B25: =IFERROR(__xludf.DUMMYFUNCTION("IF(A25<>"""", IF(COUNTA(SPLIT(TRIM(A25), "" ""))=1, LOWER(TRIM(A25)) & ""@zupee.in"", LOWER(INDEX(SPLIT(TRIM(A25), "" ""), 1)) & ""."" & LOWER(INDEX(SPLIT(TRIM(A25), "" ""), COUNTA(SPLIT(TRIM(A25), "" "")))) & ""@zupee.in"" ), """&""")"),"")
B26: =IFERROR(__xludf.DUMMYFUNCTION("IF(A26<>"""", IF(COUNTA(SPLIT(TRIM(A26), "" ""))=1, LOWER(TRIM(A26)) & ""@zupee.in"", LOWER(INDEX(SPLIT(TRIM(A26), "" ""), 1)) & ""."" & LOWER(INDEX(SPLIT(TRIM(A26), "" ""), COUNTA(SPLIT(TRIM(A26), "" "")))) & ""@zupee.in"" ), """&""")"),"")
B27: =IFERROR(__xludf.DUMMYFUNCTION("IF(A27<>"""", IF(COUNTA(SPLIT(TRIM(A27), "" ""))=1, LOWER(TRIM(A27)) & ""@zupee.in"", LOWER(INDEX(SPLIT(TRIM(A27), "" ""), 1)) & ""."" & LOWER(INDEX(SPLIT(TRIM(A27), "" ""), COUNTA(SPLIT(TRIM(A27), "" "")))) & ""@zupee.in"" ), """&""")"),"")
B28: =IFERROR(__xludf.DUMMYFUNCTION("IF(A28<>"""", IF(COUNTA(SPLIT(TRIM(A28), "" ""))=1, LOWER(TRIM(A28)) & ""@zupee.in"", LOWER(INDEX(SPLIT(TRIM(A28), "" ""), 1)) & ""."" & LOWER(INDEX(SPLIT(TRIM(A28), "" ""), COUNTA(SPLIT(TRIM(A28), "" "")))) & ""@zupee.in"" ), """&""")"),"")
B29: =IFERROR(__xludf.DUMMYFUNCTION("IF(A29<>"""", IF(COUNTA(SPLIT(TRIM(A29), "" ""))=1, LOWER(TRIM(A29)) & ""@zupee.in"", LOWER(INDEX(SPLIT(TRIM(A29), "" ""), 1)) & ""."" & LOWER(INDEX(SPLIT(TRIM(A29), "" ""), COUNTA(SPLIT(TRIM(A29), "" "")))) & ""@zupee.in"" ), """&""")"),"")
B30: =IFERROR(__xludf.DUMMYFUNCTION("IF(A30<>"""", IF(COUNTA(SPLIT(TRIM(A30), "" ""))=1, LOWER(TRIM(A30)) & ""@zupee.in"", LOWER(INDEX(SPLIT(TRIM(A30), "" ""), 1)) & ""."" & LOWER(INDEX(SPLIT(TRIM(A30), "" ""), COUNTA(SPLIT(TRIM(A30), "" "")))) & ""@zupee.in"" ), """&""")"),"")
B31: =IFERROR(__xludf.DUMMYFUNCTION("IF(A31<>"""", IF(COUNTA(SPLIT(TRIM(A31), "" ""))=1, LOWER(TRIM(A31)) & ""@zupee.in"", LOWER(INDEX(SPLIT(TRIM(A31), "" ""), 1)) & ""."" & LOWER(INDEX(SPLIT(TRIM(A31), "" ""), COUNTA(SPLIT(TRIM(A31), "" "")))) & ""@zupee.in"" ), """&""")"),"")
B32: =IFERROR(__xludf.DUMMYFUNCTION("IF(A32<>"""", IF(COUNTA(SPLIT(TRIM(A32), "" ""))=1, LOWER(TRIM(A32)) & ""@zupee.in"", LOWER(INDEX(SPLIT(TRIM(A32), "" ""), 1)) & ""."" & LOWER(INDEX(SPLIT(TRIM(A32), "" ""), COUNTA(SPLIT(TRIM(A32), "" "")))) & ""@zupee.in"" ), """&""")"),"")
B33: =IFERROR(__xludf.DUMMYFUNCTION("IF(A33<>"""", IF(COUNTA(SPLIT(TRIM(A33), "" ""))=1, LOWER(TRIM(A33)) & ""@zupee.in"", LOWER(INDEX(SPLIT(TRIM(A33), "" ""), 1)) & ""."" & LOWER(INDEX(SPLIT(TRIM(A33), "" ""), COUNTA(SPLIT(TRIM(A33), "" "")))) & ""@zupee.in"" ), """&""")"),"")
B34: =IFERROR(__xludf.DUMMYFUNCTION("IF(A34<>"""", IF(COUNTA(SPLIT(TRIM(A34), "" ""))=1, LOWER(TRIM(A34)) & ""@zupee.in"", LOWER(INDEX(SPLIT(TRIM(A34), "" ""), 1)) & ""."" & LOWER(INDEX(SPLIT(TRIM(A34), "" ""), COUNTA(SPLIT(TRIM(A34), "" "")))) & ""@zupee.in"" ), """&""")"),"")
B35: =IFERROR(__xludf.DUMMYFUNCTION("IF(A35<>"""", IF(COUNTA(SPLIT(TRIM(A35), "" ""))=1, LOWER(TRIM(A35)) & ""@zupee.in"", LOWER(INDEX(SPLIT(TRIM(A35), "" ""), 1)) & ""."" & LOWER(INDEX(SPLIT(TRIM(A35), "" ""), COUNTA(SPLIT(TRIM(A35), "" "")))) & ""@zupee.in"" ), """&""")"),"")
B36: =IFERROR(__xludf.DUMMYFUNCTION("IF(A36<>"""", IF(COUNTA(SPLIT(TRIM(A36), "" ""))=1, LOWER(TRIM(A36)) & ""@zupee.in"", LOWER(INDEX(SPLIT(TRIM(A36), "" ""), 1)) & ""."" & LOWER(INDEX(SPLIT(TRIM(A36), "" ""), COUNTA(SPLIT(TRIM(A36), "" "")))) & ""@zupee.in"" ), """&""")"),"")
B37: =IFERROR(__xludf.DUMMYFUNCTION("IF(A37<>"""", IF(COUNTA(SPLIT(TRIM(A37), "" ""))=1, LOWER(TRIM(A37)) & ""@zupee.in"", LOWER(INDEX(SPLIT(TRIM(A37), "" ""), 1)) & ""."" & LOWER(INDEX(SPLIT(TRIM(A37), "" ""), COUNTA(SPLIT(TRIM(A37), "" "")))) & ""@zupee.in"" ), """&""")"),"")
B38: =IFERROR(__xludf.DUMMYFUNCTION("IF(A38<>"""", IF(COUNTA(SPLIT(TRIM(A38), "" ""))=1, LOWER(TRIM(A38)) & ""@zupee.in"", LOWER(INDEX(SPLIT(TRIM(A38), "" ""), 1)) & ""."" & LOWER(INDEX(SPLIT(TRIM(A38), "" ""), COUNTA(SPLIT(TRIM(A38), "" "")))) & ""@zupee.in"" ), """&""")"),"")
B39: =IFERROR(__xludf.DUMMYFUNCTION("IF(A39<>"""", IF(COUNTA(SPLIT(TRIM(A39), "" ""))=1, LOWER(TRIM(A39)) & ""@zupee.in"", LOWER(INDEX(SPLIT(TRIM(A39), "" ""), 1)) & ""."" & LOWER(INDEX(SPLIT(TRIM(A39), "" ""), COUNTA(SPLIT(TRIM(A39), "" "")))) & ""@zupee.in"" ), """&""")"),"")
B40: =IFERROR(__xludf.DUMMYFUNCTION("IF(A40<>"""", IF(COUNTA(SPLIT(TRIM(A40), "" ""))=1, LOWER(TRIM(A40)) & ""@zupee.in"", LOWER(INDEX(SPLIT(TRIM(A40), "" ""), 1)) & ""."" & LOWER(INDEX(SPLIT(TRIM(A40), "" ""), COUNTA(SPLIT(TRIM(A40), "" "")))) & ""@zupee.in"" ), """&""")"),"")
...

Sheet G Suite Bulk User Creation
A1: Actions | B1: FirstName 🔂 | C1: LastName 🔂 | D1: PrimaryEmail | E1: Password 🔂 | F1: OrgUnitPath | G1: RecoveryMobile | H1: RecoveryEmail | I1: ManagerEmail | J1: JobTitle | K1: Department 🔂 | L1: Status 🔂 | M1: LastUpdated 🔂
A2: Update | B2: =IFERROR(LEFT('Emp Info'!A2,SEARCH(" ",'Emp Info'!A2)-1),'Emp Info'!A2) -> Aman | C2: =IF(ISBLANK('Emp Info'!A2), "", IFERROR(RIGHT('Emp Info'!A2,LEN('Emp Info'!A2)-SEARCH(" ",'Emp Info'!A2,1)),".")) -> Hans | D2: =IFERROR(__xludf.DUMMYFUNCTION("IF('Emp Info'!A2<>"""", IF(COUNTA(SPLIT(TRIM('Emp Info'!A2), "" ""))=1, LOWER(TRIM('Emp Info'!A2)) & ""@zupee.in"", LOWER(INDEX(SPLIT(TRIM('Emp Info'!A2), "" ""), 1)) & ""."" & LOWER(INDEX(SPLIT(TRIM('Emp Info'!A2), "" ""), COUNTA(SPLIT(TRIM('Emp Info'!A2"&"), "" "")))) & ""@zupee.in"" ), """")"),"aman.hans@zupee.in") -> aman.hans@zupee.in | E2: =rpassword(16) -> QH2b9{dCF8Kg17YM | F2: / | K2: Technology | L2: User updated successfully at 2026-03-16 12:33:47 GMT+05:30. | M2: 2026-03-16 12:33:47 GMT+05:30
A3: Update | B3: =IFERROR(LEFT('Emp Info'!A3,SEARCH(" ",'Emp Info'!A3)-1),'Emp Info'!A3) -> Harshit | C3: =IF(ISBLANK('Emp Info'!A3), "", IFERROR(RIGHT('Emp Info'!A3,LEN('Emp Info'!A3)-SEARCH(" ",'Emp Info'!A3,1)),".")) -> Kumar Singh | D3: =IFERROR(__xludf.DUMMYFUNCTION("IF('Emp Info'!A3<>"""", IF(COUNTA(SPLIT(TRIM('Emp Info'!A3), "" ""))=1, LOWER(TRIM('Emp Info'!A3)) & ""@zupee.in"", LOWER(INDEX(SPLIT(TRIM('Emp Info'!A3), "" ""), 1)) & ""."" & LOWER(INDEX(SPLIT(TRIM('Emp Info'!A3), "" ""), COUNTA(SPLIT(TRIM('Emp Info'!A3"&"), "" "")))) & ""@zupee.in"" ), """")"),"harshit.singh@zupee.in") -> harshit.singh@zupee.in | E3: =rpassword(16) -> Ll$8PrYRRMHK6thW | F3: / | K3: Data | L3: User updated successfully at 2026-03-16 12:33:47 GMT+05:30. | M3: 2026-03-16 12:33:47 GMT+05:30

Sheet Bulk Email Creation
A1: Action | B1: FirstName 🔂 | C1: LastName 🔂 | D1: PrimaryEmail | E1: Password 🔂 | F1: OrgUnitPath | G1: RecoveryMobile | H1: RecoveryEmail | I1: Status🔂 | J1: Last Updated🔂
A2: Create | B2: Admin | C2: Neoastro | D2: admin_neoastro@zupee.in | E2: =rpassword(16) -> MnZFp2HLic8BZf@e | F2: / | G2: +918595233273
A3: Create | B3: Admin | C3: Vedicsankalp | D3: admin_vedicsankalp@zupee.in | E3: =rpassword(16) -> Tl$#348GtzyU9Qx3 | F3: / | G3: +918595233273
A4: Create | B4: Admin | C4: Zupeestudio | D4: admin_zupeestudio@zupee.in | E4: =rpassword(16) -> SbV5MrY#QtoKxIYL | F4: / | G4: +918595233273
A5: Create | B5: Admin | C5: zaplearn | D5: admin_zaplearn@zupee.in | E5: =rpassword(16) -> 87Afmr4Jfr2E}si/ | F5: / | G5: +918595233273
B8: =IFERROR(LEFT(#REF!,SEARCH(" ",#REF!)-1),#REF!) -> #REF! | C8: =IF(ISBLANK(#REF!), "", IFERROR(RIGHT(#REF!,LEN(#REF!)-SEARCH(" ",#REF!,1)),".")) -> . | D8: =IF(#REF!<>"", SUBSTITUTE(LOWER(#REF!), " ", ".") & "@zupee.in", "") -> #REF! | E8: =IF(D8<>"",rpassword(16),"") -> #REF!

Sheet BulkRemove|OFFBOARDING
A1: Actions | B1: PrimaryEmail | C1: Status 🔂 | D1: LastUpdated 🔂
A2: Delete | B2: jyoti.gupta@ludozing.com | C2: Deleted | D2: 2026-02-20 15:20:33 GMT+05:30
A3: Delete | B3: jyoti.gupta@cardspatti.com | C3: Deleted | D3: 2026-02-20 15:20:33 GMT+05:30

Sheet Add Group ID_Bulk
A1: UserEmail | B1: {={"GroupEmails 🔂"; IFERROR(VLOOKUP(C2:C40, 'Org Unit Path List'!D:E, 2, FALSE), "")}} -> GroupEmails 🔂 | C1: Employee Type | D1: Status
A2: ='G Suite Bulk User Creation'!D2 -> aman.hans@zupee.in | B2: all@zupee.in | C2: Full Time
A3: =#REF! -> #REF! | B3: all@zupee.in | C3: Contractual
A4: =#REF! -> #REF! | B4: all@zupee.in | C4: Full Time
A5: =#REF! -> #REF! | B5: all@zupee.in | C5: Full Time
A6: =#REF! -> #REF! | B6: all@zupee.in | C6: Contractual
A7: =#REF! -> #REF!
A8: =#REF! -> #REF!
A9: =#REF! -> #REF!
A10: =#REF! -> #REF!
A11: =#REF! -> #REF!
A12: =#REF! -> #REF!
A13: =#REF! -> #REF!
A14: =#REF! -> #REF!

Sheet 1 Group ID_Bulk
A1: UserEmail | B1: GroupEmails | C1: Status
A2: ishank.mehta@zupee.in | B2: in.zupee.domain.only@zupee.in | C2: Done: in.zupee.domain.only@zupee.in: Already member
A3: katha.tara@zupee.in | B3: in.zupee.domain.only@zupee.in | C3: Done: in.zupee.domain.only@zupee.in: Added
A4: sairam.mushyam@zupee.in | B4: in.zupee.domain.only@zupee.in | C4: Done: in.zupee.domain.only@zupee.in: Added
A5: mohit.garg@zupee.in | B5: in.zupee.domain.only@zupee.in | C5: Done: in.zupee.domain.only@zupee.in: Added
A6: ankit.madan@zupee.in | B6: in.zupee.domain.only@zupee.in | C6: Done: in.zupee.domain.only@zupee.in: Added

Sheet Remove All Members from Groups
A1: GroupEmail | B1: Status
B2: Done: 432 members removed out of 433 listed.

Sheet Org Unit Path List
A1: Emp Type | B1: OUP | D1: Emp Type | E1: Group IDs | G1: Action
A2: Permanent/ Intern/ Trainee | B2: /No-2SV | D2: Contractual | E2: all@zupee.in | G2: Create
A3: Consultant/ Contractual | B3: / | D3: Full Time | E3: all@zupee.in | G3: Update
B4: /MDM/Development | D4: Intern | E4: all@zupee.in
B5: /MDM/Google Drive External Sharing | D5: Trainee | E5: all@zupee.in
